using ECommerce.SharedLibrary.Logs;
using ECommerce.SharedLibrary.Responses;
using Microsoft.EntityFrameworkCore;
using OrderApi.Application.Interfaces;
using OrderApi.Domain.Entities;
using OrderApi.Infrastructure.Data;
using System.Linq.Expressions;

namespace OrderApi.Infrastructure.Repositories
{
    public class OrderRepository(OrderDbContext context) : IOrderRepository
    {
        public async Task<Response> CreateAsync(Order entity)
        {
            try
            {
                var result = context.Orders.Add(entity).Entity;
                await context.SaveChangesAsync();

                return result.Id > 0 
                    ? new Response(true, "Order placed successfully") 
                    : new Response(false, "Error occurred while placing order");
            }
            catch (Exception ex) 
            {
                LogException.LogExceptions(ex);

                return new Response(false, "Error occurred while placing order");
            }
        }

        public async Task<Response> DeleteAsync(Order entity)
        {
            try
            {
                var order = await FindByIdAsync(entity.Id);

                if (order is null)
                    return new Response(false, "Order not found");

                context.Orders.Remove(order);
                await context.SaveChangesAsync();

                return new Response(true, "Order deleted successfully");
            }
            catch (Exception ex)
            {
                LogException.LogExceptions(ex);

                return new Response(false, "Error occurred while deleting order");
            }
        }

        public async Task<Order> FindByIdAsync(int id)
        {
            try
            {
                var order = await context.Orders.FindAsync(id);

                return order is not null ? order : null!;
            }
            catch (Exception ex)
            {
                LogException.LogExceptions(ex);

                throw new Exception("Error occurred while retrieving order");
            }
        }

        public async Task<IEnumerable<Order>> GetAllAsync()
        {
            try
            {
                var orders = await context.Orders.AsNoTracking().ToListAsync();

                return orders.Any() ? orders : null!;
            }
            catch (Exception ex)
            {
                LogException.LogExceptions(ex);

                throw new Exception("Error occurred while retrieving orders");
            }
        }

        public async Task<Order> GetByAsync(Expression<Func<Order, bool>> predicate)
        {
            try
            {
                var orders = await context.Orders.Where(predicate).FirstOrDefaultAsync();

                return orders is not null ? orders : null!;
            }
            catch (Exception ex)
            {
                LogException.LogExceptions(ex);

                throw new Exception("Error occurred while retrieving order");
            }
        }

        public async Task<IEnumerable<Order>> GetOrdersAsync(Expression<Func<Order, bool>> predicate)
        {
            try
            {
                var orders = await context.Orders.Where(predicate).ToListAsync();

                return orders is not null ? orders : null!;
            }
            catch (Exception ex)
            {
                LogException.LogExceptions(ex);

                throw new Exception("Error occurred while retrieving orders");
            }
        }

        public async Task<Response> UpdateAsync(Order entity)
        {
            try
            {
                var order = await FindByIdAsync(entity.Id);

                if (order is null)
                    return new Response(false, "Order not found");

                context.Entry(order).State = EntityState.Detached;

                context.Update(entity);
                await context.SaveChangesAsync();

                return new Response(true, "Order updated successfully");
            }
            catch (Exception ex)
            {
                LogException.LogExceptions(ex);

                return new Response(false, "Error occurred while deleting order");
            }
        }
    }
}
